Workbook

Sheet Báo cáo kiểm thử
A1: BÁO CÁO KIỂM THỬ - HỆ THỐNG ĐẶT VÉ XE KHÁCH
A2: Ngày lập báo cáo: 10/06/2026
A4: STT | B4: Mã Test Case | C4: Use Case | D4: Tên Test Case | E4: Điều kiện tiên quyết | F4: Dữ liệu đầu vào | G4: Bước thực hiện | H4: Kết quả mong đợi | I4: Kết quả thực tế | J4: Trạng thái | K4: Mức ưu tiên | L4: Người thực hiện | M4: Ngày thực hiện | N4: Ghi chú
A5: 1 | B5: UC01_TC01 | C5: UC1 - Đăng nhập hệ thống | D5: Đăng nhập thành công với thông tin hợp lệ | E5: Tài khoản đã đăng ký, còn hiệu lực (chưa khóa, chưa hết hạn) | F5: Email: user@example.com / Mật khẩu: đúng | G5: 1. Truy cập trang đăng nhập 2. Nhập email và mật khẩu hợp lệ 3. Nhấn "Đăng nhập" | H5: Đăng nhập thành công, chuyển đến giao diện tương ứng với vai trò, phiên làm việc được khởi tạo | I5: Đạt yêu cầu như kỳ vọng | J5: Pass | K5: Cao | L5: Nguyễn Minh Nguyệt | M5: 46183
A6: 2 | B6: UC01_TC02 | C6: UC1 - Đăng nhập hệ thống | D6: Đăng nhập sai mật khẩu | E6: Tài khoản đã đăng ký, còn hiệu lực | F6: Email: user@example.com / Mật khẩu: sai (vd "12345") | G6: 1. Truy cập trang đăng nhập 2. Nhập email đúng, mật khẩu sai 3. Nhấn "Đăng nhập" | H6: Hệ thống hiển thị thông báo lỗi "Email hoặc mật khẩu không đúng", không chuyển hướng, không tạo phiên làm việc | I6: Đạt yêu cầu như kỳ vọng | J6: Pass | K6: Cao | L6: Nguyễn Minh Nguyệt | M6: 46183
A7: 3 | B7: UC01_TC03 | C7: UC1 - Đăng nhập hệ thống | D7: Đăng nhập với tài khoản bị khóa | E7: Tài khoản tồn tại nhưng đã bị khóa | F7: Email: lockeduser@example.com / Mật khẩu: đúng | G7: 1. Truy cập trang đăng nhập 2. Nhập đúng email/mật khẩu của tài khoản bị khóa 3. Nhấn "Đăng nhập" | H7: Hệ thống từ chối truy cập, hiển thị thông báo "Tài khoản đã bị khóa", không cho vào hệ thống | I7: Đạt yêu cầu như kỳ vọng | J7: Pass | K7: Cao | L7: Nguyễn Minh Nguyệt | M7: 46183
A8: 4 | B8: UC01_TC04 | C8: UC1 - Đăng nhập hệ thống | D8: Bỏ trống các trường bắt buộc | E8: Không yêu cầu tài khoản cụ thể | F8: Email: để trống / Mật khẩu: để trống | G8: 1. Truy cập trang đăng nhập 2. Không nhập gì vào 2 trường 3. Nhấn "Đăng nhập" | H8: Hệ thống hiển thị cảnh báo validation tại các trường bắt buộc, không gửi yêu cầu lên server | I8: Đạt yêu cầu như kỳ vọng | J8: Pass | K8: Trung bình | L8: Nguyễn Minh Nguyệt | M8: 46183
A9: 5 | B9: UC01_TC05 | C9: UC1 - Đăng nhập hệ thống | D9: Nhập email sai định dạng | E9: Không yêu cầu tài khoản cụ thể | F9: Email: "userexample.com" (thiếu @ hoặc domain) / Mật khẩu: bất kỳ | G9: 1. Truy cập trang đăng nhập 2. Nhập email sai định dạng 3. Nhấn "Đăng nhập" | H9: Hệ thống hiển thị lỗi định dạng email ngay tại trường nhập, không gửi yêu cầu | I9: Đạt yêu cầu như kỳ vọng | J9: Pass | K9: Trung bình | L9: Nguyễn Minh Nguyệt | M9: 46183
A10: 6 | B10: UC02_TC01 | C10: UC2 - Quản lý nhà xe | D10: Thêm mới nhà xe thành công | E10: Admin đã đăng nhập, có phiên làm việc hợp lệ | F10: Tên nhà xe: "Mai Linh"; Hotline: "0909123456"; Email: "ptr@example.com"; các trường khác hợp lệ, chưa tồn tại | G10: 1. Truy cập menu "Quản lý nhà xe" 2. Chọn "Thêm mới" 3. Nhập đầy đủ thông tin hợp lệ 4. Nhấn "Xác nhận" | H10: Hệ thống lưu thông tin nhà xe vào database, hiển thị thông báo thành công, danh sách được cập nhật và đồng bộ lên giao diện khách hàng | I10: Đạt yêu cầu như kỳ vọng | J10: Pass | K10: Cao | L10: Nguyễn Minh Nguyệt | M10: 46183
A11: 7 | B11: UC02_TC02 | C11: UC2 - Quản lý nhà xe | D11: Thêm mới nhà xe với tên/giấy phép kinh doanh đã tồn tại | E11: Admin đã đăng nhập; hệ thống đã tồn tại nhà xe có tên "Mai Linh" | F11: Tên nhà xe: "Mai Linh" (trùng); Hotline/email khác | G11: 1. Truy cập menu "Quản lý nhà xe" 2. Chọn "Thêm mới" 3. Nhập tên nhà xe đã tồn tại 4. Nhấn "Xác nhận" | H11: Hệ thống từ chối lưu, hiển thị thông báo lỗi trùng lặp dữ liệu | I11: Đạt yêu cầu như kỳ vọng | J11: Pass | K11: Cao | L11: Nguyễn Minh Nguyệt | M11: 46183
A12: 8 | B12: UC02_TC03 | C12: UC2 - Quản lý nhà xe | D12: Để trống các trường bắt buộc khi thêm/sửa nhà xe | E12: Admin đã đăng nhập | F12: Tên nhà xe: để trống; Hotline: để trống | G12: 1. Truy cập menu "Quản lý nhà xe" 2. Chọn "Thêm mới" 3. Bỏ trống Tên nhà xe và Hotline 4. Nhấn "Xác nhận" | H12: Hệ thống từ chối lưu, hiển thị cảnh báo lỗi màu đỏ tại các trường bắt buộc đang trống | I12: Đạt yêu cầu như kỳ vọng | J12: Pass | K12: Trung bình | L12: Nguyễn Minh Nguyệt | M12: 46183
A13: 9 | B13: UC02_TC04 | C13: UC2 - Quản lý nhà xe | D13: Xóa nhà xe đang có chuyến xe hoạt động hoặc vé chờ khởi hành | E13: Admin đã đăng nhập; tồn tại nhà xe đang có chuyến xe hoạt động hoặc vé khách đang chờ khởi hành | F13: Chọn nhà xe có ràng buộc dữ liệu liên quan (chuyến/vé) | G13: 1. Truy cập menu "Quản lý nhà xe" 2. Chọn nhà xe đang vận hành 3. Nhấn "Xóa" 4. Xác nhận thao tác | H13: Hệ thống chặn thao tác xóa, hiển thị thông báo yêu cầu điều chuyển lịch trình trước khi xử lý | I13: Đạt yêu cầu như kỳ vọng | J13: Pass | K13: Cao | L13: Nguyễn Minh Nguyệt | M13: 46183
A14: 10 | B14: UC02_TC05 | C14: UC2 - Quản lý nhà xe | D14: Tìm kiếm nhà xe theo từ khóa | E14: Admin đã đăng nhập; hệ thống có sẵn danh sách nhà xe | F14: Từ khóa tìm kiếm: "Mai Linh" hoặc số điện thoại "0909123456" | G14: 1. Truy cập menu "Quản lý nhà xe" 2. Nhập từ khóa vào thanh tìm kiếm | H14: Hệ thống lọc và trả về kết quả phù hợp theo thời gian thực (real-time) | I14: Đạt yêu cầu như kỳ vọng | J14: Pass | K14: Trung bình | L14: Nguyễn Minh Nguyệt | M14: 46183
A15: 11 | B15: UC02_TC06 | C15: UC2 - Quản lý nhà xe | D15: Sửa thông tin nhà xe nhưng dữ liệu không đồng bộ ngay lên giao diện khách hàng | E15: Admin đã đăng nhập; nhà xe đang hiển thị thông tin cũ trên giao diện khách hàng | F15: Hotline mới: "0911222333" (thay cho hotline cũ) | G15: 1. Truy cập "Quản lý nhà xe" 2. Chọn nhà xe cần sửa 3. Cập nhật Hotline mới 4. Nhấn "Xác nhận" 5. Mở giao diện khách hàng kiểm tra ngay lập tức | H15: Thông tin Hotline mới được đồng bộ và hiển thị ngay lập tức trên giao diện khách hàng | I15: Giao diện khách hàng vẫn hiển thị hotline cũ trong vài phút do cơ chế cache chưa được làm mới (invalidate) sau khi cập nhật | J15: Fail | K15: Trung bình | L15: QA Team | M15: 20/06/2026 | N15: Thiếu cơ chế invalidate cache khi dữ liệu nhà xe được Admin chỉnh sửa
A16: 12 | B16: UC02_TC07 | C16: UC2 - Quản lý nhà xe | D16: Khóa nhà xe nhưng các chuyến xe của nhà xe đó vẫn hiển thị cho khách đặt vé | E16: Admin đã đăng nhập; nhà xe đang ở trạng thái "Đang hoạt động" và có các chuyến xe chưa khởi hành | F16: Nhà xe cần khóa: có các chuyến xe trong tương lai chưa khởi hành, chưa có vé bán | G16: 1. Truy cập "Quản lý nhà xe" 2. Chọn nhà xe 3. Nhấn "Khóa nhà xe" 4. Xác nhận thao tác 5. Vào giao diện khách hàng tìm kiếm chuyến xe của nhà xe vừa khóa | H16: Sau khi khóa, toàn bộ chuyến xe của nhà xe đó phải bị ẩn khỏi kết quả tìm kiếm của khách hàng | I16: Chuyến xe của nhà xe đã bị khóa vẫn hiển thị và cho phép đặt vé trên giao diện khách hàng | J16: Fail | K16: Cao | L16: QA Team | M16: 20/06/2026 | N16: Thiếu liên kết kiểm tra trạng thái nhà xe khi truy vấn danh sách chuyến xe hiển thị cho khách
A17: 13 | B17: UC04_TC01 | C17: UC4 - Quản lý tuyến đường | D17: Thêm mới tuyến đường thành công | E17: Admin đã đăng nhập thành công | F17: Điểm đi: "Hà Nội"; Điểm đến: "Đà Nẵng"; Khoảng cách: 780km; các trường khác hợp lệ, chưa trùng | G17: 1. Chọn "Quản lý tuyến đường" 2. Chọn "Thêm mới" 3. Nhập đầy đủ thông tin tuyến đường 4. Nhấn "Lưu" | H17: Hệ thống lưu tuyến đường mới vào database, hiển thị thông báo thành công, danh sách được cập nhật | I17: Đạt yêu cầu như kỳ vọng | J17: Pass | K17: Cao | L17: Nguyễn Minh Nguyệt | M17: 46183
A18: 14 | B18: UC04_TC02 | C18: UC4 - Quản lý tuyến đường | D18: Thêm tuyến đường trùng điểm đi - điểm đến với tuyến đã tồn tại | E18: Admin đã đăng nhập; hệ thống đã có tuyến "Hà Nội - Đà Nẵng" | F18: Điểm đi: "Hà Nội"; Điểm đến: "Đà Nẵng" (trùng hoàn toàn) | G18: 1. Chọn "Quản lý tuyến đường" 2. Chọn "Thêm mới" 3. Nhập điểm đi/điểm đến trùng tuyến hiện có 4. Nhấn "Lưu" | H18: Hệ thống báo lỗi "Tuyến đường này đã tồn tại", không lưu dữ liệu | I18: Đạt yêu cầu như kỳ vọng | J18: Pass | K18: Cao | L18: Nguyễn Minh Nguyệt | M18: 46183
A19: 15 | B19: UC04_TC03 | C19: UC4 - Quản lý tuyến đường | D19: Xóa tuyến đường đang có lịch trình hoạt động hoặc vé đã bán | E19: Admin đã đăng nhập; tuyến đường đang có lịch trình xuất bến hoạt động hoặc vé đã bán chưa hoàn tất | F19: Chọn tuyến đường có ràng buộc dữ liệu liên quan | G19: 1. Chọn "Quản lý tuyến đường" 2. Chọn tuyến đường đang hoạt động 3. Nhấn "Xóa" 4. Xác nhận | H19: Hệ thống thông báo lỗi "Không thể xóa tuyến đường đang có lịch trình hoạt động hoặc đơn đặt vé chưa hoàn tất", không xóa | I19: Đạt yêu cầu như kỳ vọng | J19: Pass | K19: Cao | L19: Nguyễn Minh Nguyệt | M19: 46183
A20: 16 | B20: UC04_TC04 | C20: UC4 - Quản lý tuyến đường | D20: Thay đổi trạng thái tuyến đường sang "Tạm dừng đón khách" | E20: Admin đã đăng nhập; tuyến đường đang ở trạng thái "Đang hoạt động" | F20: Tuyến đường: "Hà Nội - Đà Nẵng"; Trạng thái mới: "Tạm dừng đón khách" | G20: 1. Chọn "Quản lý tuyến đường" 2. Chọn tuyến đường cần đổi trạng thái 3. Chuyển trạng thái sang "Tạm dừng đón khách" 4. Lưu thay đổi | H20: Trạng thái tuyến được cập nhật, tuyến đường bị ẩn khỏi giao diện khách hàng, dữ liệu tuyến vẫn được giữ nguyên | I20: Đạt yêu cầu như kỳ vọng | J20: Pass | K20: Trung bình | L20: Nguyễn Minh Nguyệt | M20: 46183
A21: 17 | B21: UC04_TC05 | C21: UC4 - Quản lý tuyến đường | D21: Sửa thông tin tuyến đường với dữ liệu để trống trường bắt buộc | E21: Admin đã đăng nhập; tuyến đường đã tồn tại trên hệ thống | F21: Điểm đi: để trống; các trường khác giữ nguyên | G21: 1. Chọn "Quản lý tuyến đường" 2. Chọn tuyến đường cần sửa 3. Xóa trống trường "Điểm đi" 4. Nhấn "Lưu" | H21: Hệ thống từ chối lưu, hiển thị cảnh báo lỗi validation tại trường "Điểm đi" | I21: Đạt yêu cầu như kỳ vọng | J21: Pass | K21: Trung bình | L21: Nguyễn Minh Nguyệt | M21: 46183
A22: 18 | B22: UC04_TC06 | C22: UC4 - Quản lý tuyến đường | D22: Chuyển trạng thái tuyến sang "Tạm dừng" nhưng chuyến xe đã lên lịch không được xử lý đúng cách | E22: Admin đã đăng nhập; tuyến đường đang có các chuyến xe đã lên lịch trong tương lai | F22: Tuyến đường: "Hà Nội - Đà Nẵng"; có 3 chuyến xe đã lên lịch chưa khởi hành | G22: 1. Truy cập "Quản lý tuyến đường" 2. Chọn tuyến đang có chuyến xe đã lên lịch 3. Chuyển trạng thái sang "Tạm dừng đón khách" 4. Kiểm tra các chuyến xe đã lên lịch trên giao diện khách hàng | H22: Hệ thống cảnh báo Admin về các chuyến xe bị ảnh hưởng trước khi xác nhận, các chuyến đã có vé bán vẫn phải truy cập được bình thường để hoàn tất hành trình | I22: Hệ thống không cảnh báo, đồng thời ẩn luôn cả những chuyến xe đã có khách mua vé, khiến khách hàng không thể xem lại thông tin vé/lịch trình của mình | J22: Fail | K22: Cao | L22: QA Team | M22: 20/06/2026 | N22: Thiếu logic phân tách giữa việc ẩn tuyến khỏi tìm kiếm mới và việc giữ quyền truy cập của vé đã bán
A23: 19 | B23: UC08_TC01 | C23: UC8 - Quản lý vé | D23: Tìm kiếm vé theo mã vé thành công | E23: Admin đã đăng nhập; tồn tại đơn vé với mã đã biết trên hệ thống | F23: Mã vé: "VE001234" | G23: 1. Chọn "Quản lý vé" 2. Nhập mã vé vào thanh tìm kiếm 3. Nhấn tìm kiếm | H23: Hệ thống trả về đúng thông tin đơn vé tương ứng với mã đã nhập | I23: Đạt yêu cầu như kỳ vọng | J23: Pass | K23: Cao | L23: Nguyễn Minh Nguyệt | M23: 46183
A24: 20 | B24: UC08_TC02 | C24: UC8 - Quản lý vé | D24: Tìm kiếm với mã vé không tồn tại | E24: Admin đã đăng nhập | F24: Mã vé: "VE999999" (không tồn tại trên hệ thống) | G24: 1. Chọn "Quản lý vé" 2. Nhập mã vé không tồn tại 3. Nhấn tìm kiếm | H24: Hệ thống trả về danh sách trống, hiển thị thông báo "Mã vé không tồn tại trên hệ thống" | I24: Đạt yêu cầu như kỳ vọng | J24: Pass | K24: Trung bình | L24: Nguyễn Minh Nguyệt | M24: 46183
A25: 21 | B25: UC08_TC03 | C25: UC8 - Quản lý vé | D25: Cập nhật trạng thái vé (xác nhận hoàn tiền hủy vé) | E25: Admin đã đăng nhập; tồn tại vé ở trạng thái "Đã thanh toán" chưa khởi hành | F25: Mã vé hợp lệ; trạng thái mới: "Đã hủy/Đã hoàn tiền" | G25: 1. Chọn "Quản lý vé" 2. Tìm và chọn vé cần xử lý 3. Cập nhật trạng thái thành "Đã hoàn tiền" 4. Xác nhận | H25: Hệ thống ghi nhận trạng thái mới, gửi email thông báo cập nhật cho khách hàng | I25: Đạt yêu cầu như kỳ vọng | J25: Pass | K25: Cao | L25: Nguyễn Minh Nguyệt | M25: 46183
A26: 22 | B26: UC08_TC04 | C26: UC8 - Quản lý vé | D26: Đổi chuyến/điều chuyển vé cho khách | E26: Admin đã đăng nhập; vé hiện tại hợp lệ, chuyến mới còn ghế trống | F26: Mã vé cũ; chuyến xe mới còn ghế trống | G26: 1. Chọn "Quản lý vé" 2. Chọn vé cũ cần đổi 3. Nhấn "Đổi lịch trình" 4. Chọn chuyến xe mới còn ghế trống 5. Xác nhận | H26: Hệ thống cập nhật lại thông tin mã vé sang chuyến mới, không làm thay đổi lịch sử dòng tiền thanh toán | I26: Đạt yêu cầu như kỳ vọng | J26: Pass | K26: Trung bình | L26: Nguyễn Minh Nguyệt | M26: 46183
A27: 23 | B27: UC08_TC05 | C27: UC8 - Quản lý vé | D27: Chặn sửa vé thuộc chuyến đã hoàn tất hành trình | E27: Admin đã đăng nhập; vé thuộc về chuyến xe đã khởi hành và kết thúc trong quá khứ | F27: Mã vé thuộc chuyến đã hoàn tất hành trình | G27: 1. Chọn "Quản lý vé" 2. Tìm vé thuộc chuyến đã kết thúc 3. Thử chỉnh sửa thông tin/trạng thái vé | H27: Hệ thống chặn quyền chỉnh sửa, hiển thị thông báo "Vé đã hoàn tất hành trình, không cho phép chỉnh sửa dữ liệu" | I27: Đạt yêu cầu như kỳ vọng | J27: Pass | K27: Cao | L27: Nguyễn Minh Nguyệt | M27: 46183
A28: 24 | B28: UC13_TC01 | C28: UC13 - Đặt vé | D28: Đặt vé và thanh toán thành công | E28: Người dùng đã đăng nhập tài khoản thành viên hợp lệ | F28: Điểm đi: "TP.HCM"; Điểm đến: "Đà Lạt"; Ngày đi hợp lệ; ghế trống bất kỳ; phương thức thanh toán hợp lệ | G28: 1. Nhập điểm đi, điểm đến, ngày đi 2. Chọn chuyến xe phù hợp 3. Chọn ghế trống trên sơ đồ 4. Xác nhận thông tin, chọn thanh toán online 5. Thực hiện thanh toán thành công | H28: Hệ thống xác nhận giao dịch, đổi trạng thái ghế thành "Đã bán", tạo mã vé điện tử (QR), gửi vé về email khách hàng | I28: Đạt yêu cầu như kỳ vọng | J28: Pass | K28: Cao | L28: Nguyễn Minh Nguyệt | M28: 46183
A29: 25 | B29: UC13_TC02 | C29: UC13 - Đặt vé | D29: Cơ chế giữ chỗ tạm thời (Seat Blocking) khi chưa thanh toán | E29: Người dùng đã đăng nhập; đã chọn ghế và tiến hành thanh toán nhưng chưa hoàn tất | F29: Ghế đã chọn; thời gian chờ > 10 phút không thanh toán | G29: 1. Chọn ghế và bấm tiến hành thanh toán 2. Không thực hiện thanh toán, chờ quá 10 phút | H29: Hệ thống tự động nhả ghế về trạng thái trống sau 10 phút, ghế được mở lại cho người khác chọn | I29: Đạt yêu cầu như kỳ vọng | J29: Pass | K29: Cao | L29: Nguyễn Minh Nguyệt | M29: 46183
A30: 26 | B30: UC13_TC03 | C30: UC13 - Đặt vé | D30: Ghế đã bị người khác đặt trước khi xác nhận thanh toán | E30: Người dùng đã đăng nhập; cùng lúc có phiên làm việc khác đã khóa/mua ghế đó trước | F30: Ghế: vị trí đã bị một phiên khác giữ/mua trong tích tắc trước khi xác nhận | G30: 1. Chọn ghế trên sơ đồ 2. Tiến hành xác nhận đặt vé 3. Hệ thống kiểm tra lại trạng thái ghế | H30: Hệ thống báo lỗi "Vị trí ghế đã có người đặt, vui lòng chọn lại ghế khác", không cho tiếp tục với ghế đó | I30: Đạt yêu cầu như kỳ vọng | J30: Pass | K30: Cao | L30: Nguyễn Minh Nguyệt | M30: 46183
A31: 27 | B31: UC13_TC04 | C31: UC13 - Đặt vé | D31: Thanh toán thất bại hoặc người dùng hủy giao dịch | E31: Người dùng đã đăng nhập; đã chọn ghế và chuyển sang cổng thanh toán | F31: Thông tin thanh toán không hợp lệ hoặc người dùng bấm "Quay lại" hủy giao dịch | G31: 1. Tiến hành thanh toán tại cổng mô phỏng 2. Giao dịch trả về lỗi, hoặc người dùng bấm "Quay lại" | H31: Hệ thống giải phóng ghế đang giữ tạm thời, đơn vé chuyển trạng thái "Thanh toán thất bại/Hủy giao dịch" | I31: Đạt yêu cầu như kỳ vọng | J31: Pass | K31: Cao | L31: Nguyễn Minh Nguyệt | M31: 46183
A32: 28 | B32: UC13_TC05 | C32: UC13 - Đặt vé | D32: Tìm kiếm chuyến xe không có kết quả phù hợp | E32: Người dùng đã đăng nhập | F32: Điểm đi: "Hà Nội"; Điểm đến: "Cà Mau"; Ngày đi không có chuyến xe nào hoạt động trên tuyến này | G32: 1. Nhập điểm đi, điểm đến, ngày đi 2. Nhấn tìm kiếm chuyến xe | H32: Hệ thống hiển thị thông báo không tìm thấy chuyến xe phù hợp, không hiển thị danh sách chuyến | I32: Đạt yêu cầu như kỳ vọng | J32: Pass | K32: Trung bình | L32: Nguyễn Minh Nguyệt | M32: 46183
A33: 29 | B33: UC13_TC07 | C33: UC13 - Đặt vé | D33: Mã QR vé không được gửi về email sau khi thanh toán thành công | E33: Người dùng đã đăng nhập, đã thanh toán thành công cho vé vừa đặt | F33: Email tài khoản hợp lệ, đã xác thực; giao dịch thanh toán đã được hệ thống xác nhận | G33: 1. Hoàn tất thanh toán thành công 2. Hệ thống hiển thị màn hình "Đặt vé thành công" 3. Kiểm tra hộp thư email của khách hàng trong vòng 5 phút | H33: Mã vé điện tử kèm mã QR phải được gửi đến email khách hàng ngay sau khi thanh toán thành công | I33: Email chứa mã vé/QR không được gửi đi do lỗi hàng đợi gửi mail (mail queue), khách hàng chỉ thấy vé trên màn hình mà không nhận được email xác nhận | J33: Fail | K33: Trung bình | L33: QA Team | M33: 20/06/2026 | N33: Thiếu cơ chế retry/giám sát hàng đợi gửi email khi gửi mã vé điện tử thất bại
A34: 30 | B34: UC16_TC01 | C34: UC16 - Quản lý thông tin cá nhân | D34: Cập nhật thông tin cá nhân thành công | E34: Người dùng đã đăng nhập thành công, đang ở giao diện tài khoản | F34: Tên: "Nguyễn Văn A"; Email: "vana@example.com"; SĐT: "0901234567" (chưa tồn tại) | G34: 1. Chọn trang thông tin cá nhân 2. Bấm "Chỉnh sửa thông tin" 3. Thay đổi Tên, Email, SĐT hợp lệ 4. Nhấn "Lưu thay đổi" | H34: Hệ thống kiểm tra hợp lệ, cập nhật thông tin mới vào database, hiển thị thông báo "Cập nhật thông tin thành công" | I34: Đạt yêu cầu như kỳ vọng | J34: Pass | K34: Cao | L34: Nguyễn Minh Nguyệt | M34: 46183
A35: 31 | B35: UC16_TC02 | C35: UC16 - Quản lý thông tin cá nhân | D35: Hủy chỉnh sửa thông tin cá nhân | E35: Người dùng đã đăng nhập, đang ở giao diện tài khoản | F35: Tên/Email/SĐT: đã chỉnh sửa một số trường nhưng chưa lưu | G35: 1. Chọn trang thông tin cá nhân 2. Bấm "Chỉnh sửa thông tin" 3. Thay đổi một vài thông tin 4. Nhấn "Hủy" | H35: Hệ thống quay lại màn hình thông tin cũ, không lưu bất kỳ thay đổi nào | I35: Đạt yêu cầu như kỳ vọng | J35: Pass | K35: Trung bình | L35: Nguyễn Minh Nguyệt | M35: 46183
A36: 32 | B36: UC16_TC03 | C36: UC16 - Quản lý thông tin cá nhân | D36: Cập nhật Email sai định dạng | E36: Người dùng đã đăng nhập, đang ở giao diện chỉnh sửa thông tin cá nhân | F36: Email: "vanaexample.com" (thiếu ký tự @) | G36: 1. Bấm "Chỉnh sửa thông tin" 2. Nhập Email sai định dạng 3. Nhấn "Lưu thay đổi" | H36: Hệ thống dừng luồng, không lưu, hiển thị thông báo lỗi định dạng email tại trường nhập (tiếng Việt) | I36: Đạt yêu cầu như kỳ vọng | J36: Pass | K36: Cao | L36: Nguyễn Minh Nguyệt | M36: 46183
A37: 33 | B37: UC16_TC04 | C37: UC16 - Quản lý thông tin cá nhân | D37: Cập nhật Số điện thoại không đúng 10 số | E37: Người dùng đã đăng nhập, đang ở giao diện chỉnh sửa thông tin cá nhân | F37: Số điện thoại: "09012" (5 số) hoặc "090123456789" (quá 10 số) | G37: 1. Bấm "Chỉnh sửa thông tin" 2. Nhập SĐT không đúng 10 số 3. Nhấn "Lưu thay đổi" | H37: Hệ thống dừng luồng, không lưu, hiển thị thông báo lỗi "Số điện thoại không hợp lệ" tại trường nhập | I37: Đạt yêu cầu như kỳ vọng | J37: Pass | K37: Cao | L37: Nguyễn Minh Nguyệt | M37: 46183
A38: 34 | B38: UC16_TC05 | C38: UC16 - Quản lý thông tin cá nhân | D38: Cập nhật Email/SĐT đã được sử dụng bởi tài khoản khác | E38: Người dùng đã đăng nhập; trên hệ thống đã tồn tại tài khoản khác dùng Email/SĐT này | F38: Email: "existeduser@example.com" (đã được tài khoản khác sử dụng) | G38: 1. Bấm "Chỉnh sửa thông tin" 2. Nhập Email đã tồn tại trên hệ thống (thuộc tài khoản khác) 3. Nhấn "Lưu thay đổi" | H38: Hệ thống từ chối lưu, hiển thị thông báo lỗi "Email/Số điện thoại này đã được sử dụng" | I38: Đạt yêu cầu như kỳ vọng | J38: Pass | K38: Cao | L38: Nguyễn Minh Nguyệt | M38: 46183
A39: 35 | B39: UC20_TC01 | C39: UC20 - Xử lý thanh toán | D39: Thanh toán thành công qua cổng thanh toán đối tác | E39: Đơn đặt vé đã khởi tạo thành công; khách hàng đã chọn phương thức thanh toán (thẻ/ví điện tử) | F39: Thông tin thẻ/ví điện tử hợp lệ, đủ số dư | G39: 1. Khách hàng xác nhận thanh toán 2. Hệ thống chuyển hướng đến cổng thanh toán đối tác 3. Người dùng nhập thông tin và xác thực thanh toán 4. Hệ thống nhận phản hồi từ cổng thanh toán | H39: Hệ thống cập nhật trạng thái đơn hàng thành "Đã thanh toán", hiển thị màn hình chúc mừng đặt vé thành công, ghế được xác nhận khóa thành công | I39: Đạt yêu cầu như kỳ vọng | J39: Pass | K39: Cao | L39: Nguyễn Minh Nguyệt | M39: 46183
A40: 36 | B40: UC20_TC02 | C40: UC20 - Xử lý thanh toán | D40: Khách hàng hủy giao dịch giữa chừng tại cổng thanh toán | E40: Đơn đặt vé đã khởi tạo; khách hàng đã được chuyển hướng đến trang thanh toán của đối tác | F40: Không nhập/hoàn tất thông tin thanh toán | G40: 1. Tại giao diện cổng thanh toán đối tác, khách hàng bấm "Hủy và quay lại trang web" | H40: Hệ thống nhận diện hành động hủy, hủy phiên giao dịch hiện tại, đưa khách hàng về trang chọn phương thức thanh toán cũ, đơn hàng không bị đánh dấu "Đã thanh toán" | I40: Đạt yêu cầu như kỳ vọng | J40: Pass | K40: Trung bình | L40: Nguyễn Minh Nguyệt | M40: 46183
A41: 37 | B41: UC20_TC03 | C41: UC20 - Xử lý thanh toán | D41: Thanh toán thất bại do số dư tài khoản không đủ | E41: Đơn đặt vé đã khởi tạo; khách hàng đã chọn phương thức thanh toán bằng thẻ/ví có số dư không đủ | F41: Thông tin thẻ/ví hợp lệ nhưng số dư không đủ để thanh toán | G41: 1. Khách hàng xác nhận thanh toán 2. Chuyển hướng đến cổng thanh toán 3. Nhập thông tin và xác thực 4. Cổng thanh toán phản hồi giao dịch thất bại | H41: Hệ thống chuyển trạng thái đơn thành "Thanh toán thất bại", hiển thị thông báo mời người dùng thử lại hoặc chọn phương thức khác | I41: Đạt yêu cầu như kỳ vọng | J41: Pass | K41: Cao | L41: Nguyễn Minh Nguyệt | M41: 46183
...

Sheet Tổng hợp
A1: TỔNG HỢP KẾT QUẢ KIỂM THỬ
A3: Use Case | B3: Tổng số Test Case | C3: Pass | D3: Fail | E3: Tỷ lệ thành công
A4: UC1 - Đăng nhập hệ thống | B4: =COUNTIF('Báo cáo kiểm thử'!C5:C43,A4) -> 5 | C4: =COUNTIFS('Báo cáo kiểm thử'!C5:C43,A4,'Báo cáo kiểm thử'!J5:J43,"Pass") -> 5 | D4: =B4-C4 -> 0 | E4: =C4/B4 -> 1
A5: UC2 - Quản lý nhà xe | B5: =COUNTIF('Báo cáo kiểm thử'!C5:C43,A5) -> 7 | C5: =COUNTIFS('Báo cáo kiểm thử'!C5:C43,A5,'Báo cáo kiểm thử'!J5:J43,"Pass") -> 5 | D5: =B5-C5 -> 2 | E5: =C4/B4 -> 1
A6: UC4 - Quản lý tuyến đường | B6: =COUNTIF('Báo cáo kiểm thử'!C5:C43,A6) -> 6 | C6: =COUNTIFS('Báo cáo kiểm thử'!C5:C43,A6,'Báo cáo kiểm thử'!J5:J43,"Pass") -> 5 | D6: =B6-C6 -> 1 | E6: =C5/B5 -> 0.71428571
A7: UC8 - Quản lý vé | B7: =COUNTIF('Báo cáo kiểm thử'!C5:C43,A7) -> 5 | C7: =COUNTIFS('Báo cáo kiểm thử'!C5:C43,A7,'Báo cáo kiểm thử'!J5:J43,"Pass") -> 5 | D7: =B7-C7 -> 0 | E7: =C6/B6 -> 0.83333333
A8: UC13 - Đặt vé | B8: =COUNTIF('Báo cáo kiểm thử'!C5:C43,A8) -> 6 | C8: =COUNTIFS('Báo cáo kiểm thử'!C5:C43,A8,'Báo cáo kiểm thử'!J5:J43,"Pass") -> 5 | D8: =B8-C8 -> 1 | E8: =C7/B7 -> 1
A9: UC16 - Quản lý thông tin cá nhân | B9: =COUNTIF('Báo cáo kiểm thử'!C5:C43,A9) -> 5 | C9: =COUNTIFS('Báo cáo kiểm thử'!C5:C43,A9,'Báo cáo kiểm thử'!J5:J43,"Pass") -> 5 | D9: =B9-C9 -> 0 | E9: =C8/B8 -> 0.83333333
A10: UC20 - Xử lý thanh toán | B10: 9 | C10: 5 | D10: =B10-C10 -> 4 | E10: =C9/B9 -> 1
A11: TỔNG CỘNG | B11: =SUM(B4:B10) -> 43 | C11: =SUM(C4:C10) -> 35 | D11: =SUM(D4:D10) -> 8 | E11: =C10/B10 -> 0.55555556
